[2021-12-18 17:30:26,153] {taskinstance.py:876} INFO - Dependencies all met for <TaskInstance: rank_update.git_push 2021-12-18T17:20:00+00:00 [queued]>
[2021-12-18 17:30:26,168] {taskinstance.py:876} INFO - Dependencies all met for <TaskInstance: rank_update.git_push 2021-12-18T17:20:00+00:00 [queued]>
[2021-12-18 17:30:26,174] {taskinstance.py:1067} INFO - 
--------------------------------------------------------------------------------
[2021-12-18 17:30:26,174] {taskinstance.py:1068} INFO - Starting attempt 1 of 1
[2021-12-18 17:30:26,175] {taskinstance.py:1069} INFO - 
--------------------------------------------------------------------------------
[2021-12-18 17:30:26,199] {taskinstance.py:1087} INFO - Executing <Task(BashOperator): git_push> on 2021-12-18T17:20:00+00:00
[2021-12-18 17:30:26,200] {standard_task_runner.py:52} INFO - Started process 18698 to run task
[2021-12-18 17:30:26,218] {standard_task_runner.py:76} INFO - Running: ['airflow', 'tasks', 'run', 'rank_update', 'git_push', '2021-12-18T17:20:00+00:00', '--job-id', '211', '--pool', 'default_pool', '--raw', '--subdir', 'DAGS_FOLDER/rank_update.py', '--cfg-path', '/tmp/tmprfsuq59w', '--error-file', '/tmp/tmpamhcedek']
[2021-12-18 17:30:26,220] {standard_task_runner.py:77} INFO - Job 211: Subtask git_push
[2021-12-18 17:30:26,320] {logging_mixin.py:104} INFO - Running <TaskInstance: rank_update.git_push 2021-12-18T17:20:00+00:00 [running]> on host airflowvm
[2021-12-18 17:30:26,511] {taskinstance.py:1280} INFO - Exporting the following env vars:
AIRFLOW_CTX_DAG_OWNER=airflow
AIRFLOW_CTX_DAG_ID=rank_update
AIRFLOW_CTX_TASK_ID=git_push
AIRFLOW_CTX_EXECUTION_DATE=2021-12-18T17:20:00+00:00
AIRFLOW_CTX_DAG_RUN_ID=scheduled__2021-12-18T17:20:00+00:00
[2021-12-18 17:30:26,519] {subprocess.py:52} INFO - Tmp dir root location: 
 /tmp
[2021-12-18 17:30:26,520] {subprocess.py:63} INFO - Running command: ['bash', '-c', 'git --git-dir=/home/airflow/AlgorithmStudy_211124/.git/ --work-tree=/home/airflow/AlgorithmStudy_211124/.git/ push']
[2021-12-18 17:30:26,535] {subprocess.py:75} INFO - Output:
[2021-12-18 17:31:14,303] {subprocess.py:79} INFO - remote: No anonymous write access.
[2021-12-18 17:31:14,305] {subprocess.py:79} INFO - fatal: Authentication failed for 'https://github.com/nicework-jin/AlgorithmStudy_211124/'
[2021-12-18 17:31:14,312] {subprocess.py:83} INFO - Command exited with return code 128
[2021-12-18 17:31:14,334] {taskinstance.py:1481} ERROR - Task failed with exception
Traceback (most recent call last):
  File "/home/airflow/sandbox/lib/python3.8/site-packages/airflow/models/taskinstance.py", line 1137, in _run_raw_task
    self._prepare_and_execute_task_with_callbacks(context, task)
  File "/home/airflow/sandbox/lib/python3.8/site-packages/airflow/models/taskinstance.py", line 1311, in _prepare_and_execute_task_with_callbacks
    result = self._execute_task(context, task_copy)
  File "/home/airflow/sandbox/lib/python3.8/site-packages/airflow/models/taskinstance.py", line 1341, in _execute_task
    result = task_copy.execute(context=context)
  File "/home/airflow/sandbox/lib/python3.8/site-packages/airflow/operators/bash.py", line 180, in execute
    raise AirflowException('Bash command failed. The command returned a non-zero exit code.')
airflow.exceptions.AirflowException: Bash command failed. The command returned a non-zero exit code.
[2021-12-18 17:31:14,336] {taskinstance.py:1524} INFO - Marking task as FAILED. dag_id=rank_update, task_id=git_push, execution_date=20211218T172000, start_date=20211218T173026, end_date=20211218T173114
[2021-12-18 17:31:14,370] {local_task_job.py:151} INFO - Task exited with return code 1
